Workbook

Sheet 1. Instructions
A1: Workshop — Community & Regional Carbon Mapping · Ground-data sheet
B2: Companion to the Regional Map Updating Framework workshop (docs/workshop.html), Step 2 — Process and harmonize the ground data. Adapted from the WWF-Canada Blue Carbon Eelgrass workshop digital data sheet (Measuring Carbon in Coastal Sediments, 2026); see WHAT CHANGED below.
A4: WHAT THIS WORKBOOK IS FOR
B5: Deliverable 02 of the workshop's first deliverable list: raw measurements → carbon stock → depth harmonisation → the response variable, with every unit conversion visible. Do the arithmetic here first; the R code in R/step02_harmonize_depths.R has to reproduce these numbers before it is trusted.
A7: HOW TO USE THIS WORKBOOK
A8: Sheet 2 — Core Log | B8: One row per CORE. Enter the core's position, an optional compaction factor, and landform/cover notes. Slice count, recovered length and in-situ depth calculate themselves from sheet 3.
A9: Sheet 3 — Sample Data | B9: One row per SLICE. Enter the field columns before you leave site, then add the lab columns when results come back. Everything else calculates.
A10: Sheet 4 — Core Summary | B10: Per-core totals and the depth-harmonised stocks. Fully automatic — nothing to type here.
A11: Sheet 5 — R export (layers) | B11: The flat table scripts/run_02_harmonize_depths.R reads. Save as CSV to data/soil_cores_raw.csv — column names must stay exactly as they are.
A12: Sheet 6 — R export (plots) | B12: One row per core, carrying plot_id + observed, for scripts/run_03_extract_covariates.R. Save as CSV, or build the point layer data/field_plots.gpkg from it.
A14: COLOUR KEY
A15: Yellow fill / blue text | B15: Data you type — from the field or from the lab report.
A16: Grey fill / black text | B16: Calculated. Do not type over these — you will break the column.
A17: Green text | B17: Pulled from another sheet in this workbook.
B18: There is no worked-example row: sheet 3 is populated with the project's real cores, so the data itself is the example.
A20: THE FIVE BANDS ON SHEET 3
A21: 1. Data from the field | B21: Year, core and sample id, position, measured slice thickness, coarse-fragment fraction. Copy directly from the field data sheet.
A22: 2. Calculated before the lab | B22: Slices stacked from the surface into depth-from / depth-to, then corrected to in-situ depths using the core's compaction factor.
A23: 3. Measured by the lab | B23: Dry bulk density, organic matter by loss-on-ignition, and organic carbon.
A24: 4. Calculated after the lab | B24: Carbon density and the carbon stock of each slice, in three units.
A25: 5. Harmonised to target depths | B25: Each slice's contribution to the workshop's target intervals 0–15, 15–30, 30–50, 50–100 cm, split by how much of the target each slice covers — the overlap-weighting in Step 2b of the workshop.
A26: Cross-check (cols Y–Z) | B26: The carbon density recomputed here, minus the value supplied in community_soil_cores.csv. Should be 0.000000 on every row.
A28: THE THREE EQUATIONS
A29: Carbon density (g C/cm³) | B29: bulk density (g/cm³) × organic carbon (%) / 100 × (1 − coarse-fragment fraction)
A30: Slice stock (g C/cm²) | B30: carbon density (g C/cm³) × measured slice thickness (cm)
A31: Unit conversions | B31: 1 g C/cm² = 10 kg C/m² = 100 Mg C/ha
A32: Harmonised stock | B32: carbon density × (overlap of the slice with the target interval, cm) × 10, summed over the core
A34: UNITS
A35: Depths / thickness | B35: centimetres (cm)
A36: Dry bulk density | B36: g/cm³
A37: Organic matter, organic carbon | B37: percent (0–100). Some labs return a decimal fraction (0–1) — check before entering.
A38: soc on sheet 5 | B38: g/kg, which is simply %C × 10 — the unit soilassessment::depthharm() is given.
A39: Carbon stock | B39: reported per slice as g C/cm², kg C/m² and Mg C/ha. The prior maps in CarbonResources_Assets+Covariates are in kg C/m²; the workshop text uses Mg C/ha.
A41: WHAT CHANGED FROM THE EELGRASS VERSION
A42: Compaction | B42: Reduced from a computed block (corer diameter + two insertion depths) to ONE optional factor per core on sheet 2, because the community dataset arrives with bulk density already computed and no insertion depths recorded. Blank = 1.00 = no correction. The rule is unchanged: compaction corrects DEPTHS, not stocks — the dry mass in the tube already came from a taller in-situ column, so applying the factor to the stock as well double-counts it.
A43: Corer diameter, wet/dry weights, sample volume | B43: Removed. Those columns existed to derive bulk density; here the lab reports it directly. Put them back if you start coring for bulk density yourself — and measure the corer's INTERNAL diameter with calipers, because volume sits in the denominator of bulk density and an assumed diameter biases every stock.
A44: Depth harmonisation | B44: New band 5. The eelgrass sheet stopped at per-slice stocks; this workflow needs stocks on the workshop's fixed target intervals so cores with different slicing are comparable and can be joined to raster priors.
A45: Units | B45: Stocks now also in kg C/m² and Mg C/ha, the units the prior maps and the workshop use.
A46: R export sheets | B46: New sheets 5 and 6, shaped to the column names scripts/run_02 and scripts/run_03 expect.
A48: WHAT CAUGHT US OUT IN THIS DATASET
...

Sheet 2. Core Log
A1: Sheet 2 — Core Log (one row per CORE)
A2: Compaction factor = in-situ core length ÷ recovered length. Leave blank if you did not measure it — blank is treated as 1.00 (no correction). It corrects DEPTHS only, never stocks.
A4: Core Id | B4: Year | C4: Latitude (°N) | D4: Longitude (°E, corrected) | E4: Longitude as supplied | F4: Compaction factor (optional) | G4: Compaction factor used | H4: Slices recorded | I4: Recovered core length (cm) | J4: In-situ core depth (cm) | K4: Landform / cover | L4: Notes
A5: PM-01-A | B5: 2024 | C5: 56.098575 | D5: -87.67978 | E5: 87.67978 | G5: =IF(F5="",1,F5) -> 1 | H5: =COUNTIF('3. Sample Data'!$B$6:$B$27,A5) -> 1 | I5: =SUMIF('3. Sample Data'!$B$6:$B$27,A5,'3. Sample Data'!$F$6:$F$27) -> 14.5 | J5: =I5*G5 -> 14.5
A6: PM-02-A | B6: 2024 | C6: 56.099636 | D6: -87.65064 | E6: 87.65064 | G6: =IF(F6="",1,F6) -> 1 | H6: =COUNTIF('3. Sample Data'!$B$6:$B$27,A6) -> 2 | I6: =SUMIF('3. Sample Data'!$B$6:$B$27,A6,'3. Sample Data'!$F$6:$F$27) -> 20.7 | J6: =I6*G6 -> 20.7
A7: PM-03-A | B7: 2024 | C7: 56.110356 | D7: -87.67839 | E7: 87.67839 | G7: =IF(F7="",1,F7) -> 1 | H7: =COUNTIF('3. Sample Data'!$B$6:$B$27,A7) -> 4 | I7: =SUMIF('3. Sample Data'!$B$6:$B$27,A7,'3. Sample Data'!$F$6:$F$27) -> 30.725 | J7: =I7*G7 -> 30.725
A8: FS-05 | B8: 2025 | C8: 56.079389 | D8: -87.75622 | E8: 87.75622 | G8: =IF(F8="",1,F8) -> 1 | H8: =COUNTIF('3. Sample Data'!$B$6:$B$27,A8) -> 3 | I8: =SUMIF('3. Sample Data'!$B$6:$B$27,A8,'3. Sample Data'!$F$6:$F$27) -> 30 | J8: =I8*G8 -> 30
A9: FS-04 | B9: 2025 | C9: 56.074278 | D9: -87.79556 | E9: 87.79556 | G9: =IF(F9="",1,F9) -> 1 | H9: =COUNTIF('3. Sample Data'!$B$6:$B$27,A9) -> 3 | I9: =SUMIF('3. Sample Data'!$B$6:$B$27,A9,'3. Sample Data'!$F$6:$F$27) -> 30 | J9: =I9*G9 -> 30
A10: FS-03 | B10: 2025 | C10: 56.128917 | D10: -87.87181 | E10: 87.87181 | G10: =IF(F10="",1,F10) -> 1 | H10: =COUNTIF('3. Sample Data'!$B$6:$B$27,A10) -> 3 | I10: =SUMIF('3. Sample Data'!$B$6:$B$27,A10,'3. Sample Data'!$F$6:$F$27) -> 30 | J10: =I10*G10 -> 30
A11: FS-02 | B11: 2025 | C11: 55.992611 | D11: -87.62825 | E11: 87.62825 | G11: =IF(F11="",1,F11) -> 1 | H11: =COUNTIF('3. Sample Data'!$B$6:$B$27,A11) -> 3 | I11: =SUMIF('3. Sample Data'!$B$6:$B$27,A11,'3. Sample Data'!$F$6:$F$27) -> 30 | J11: =I11*G11 -> 30
A12: FS-01 | B12: 2025 | C12: 55.965999 | D12: -87.6282 | E12: 87.6282 | G12: =IF(F12="",1,F12) -> 1 | H12: =COUNTIF('3. Sample Data'!$B$6:$B$27,A12) -> 3 | I12: =SUMIF('3. Sample Data'!$B$6:$B$27,A12,'3. Sample Data'!$F$6:$F$27) -> 30 | J12: =I12*G12 -> 30

Sheet 3. Sample Data
A1: Sheet 3 — Sample Data (one row per SLICE)
A2: Organic matter → organic carbon factor: | C2: 0.58 | D2: van Bemmelen. Used only where 'Organic carbon, measured (%C)' (column O) is blank. In this dataset %C / OM = 0.58 on every row, so the supplied %C is itself LOI-derived, not an independent measurement.
A3: Target depth intervals are the workshop's: 0–15, 15–30, 30–50, 50–100 cm. Changing them means editing the four formulas in columns U–X.
A4: 1. Data from the field | H4: 2. Calculated before the lab | M4: 3. Measured by the lab | P4: 4. Calculated after the lab | U4: 5. Harmonised to target depths (kg C/m²) | Y4: Cross-check vs. source file
A5: Year | B5: Core Id | C5: Sample Id | D5: Latitude (°N) | E5: Longitude (°E, corrected) | F5: Measured slice thickness (cm) | G5: Coarse-fragment fraction (0–1) | H5: Depth from, measured (cm) | I5: Depth to, measured (cm) | J5: Compaction factor | K5: In-situ depth from (cm) | L5: In-situ depth to (cm) | M5: Dry bulk density (g/cm³) | N5: Organic matter, LOI (%) | O5: Organic carbon, measured (%C) | P5: Organic carbon used (%C) | Q5: Carbon density (g C/cm³) | R5: Slice stock (g C/cm²) | S5: Slice stock (kg C/m²) | T5: Slice stock (Mg C/ha) | U5: → 0–15 cm | V5: → 15–30 cm | W5: → 30–50 cm | X5: → 50–100 cm | Y5: C density as supplied (g/cm³) | Z5: Check: this sheet − supplied
A6: 2024 | B6: PM-01-A | C6: PM-01-A | D6: 56.098575 | E6: -87.67978 | F6: 14.5 | G6: 0 | H6: 0 | I6: =H6+F6 -> 14.5 | J6: =IFERROR(INDEX('2. Core Log'!$G$5:$G$12,MATCH(B6,'2. Core Log'!$A$5:$A$12,0)),1) -> 1 | K6: =H6*J6 -> 0 | L6: =I6*J6 -> 14.5 | M6: 0.0929 | N6: 39.1 | O6: 22.7 | P6: =IF(O6="",N6*$C$2,O6) -> 22.7 | Q6: =M6*P6/100*(1-G6) -> 0.0210883 | R6: =Q6*F6 -> 0.30578035 | S6: =R6*10 -> 3.0578035 | T6: =S6*10 -> 30.578035 | U6: =MAX(0,MIN($L6,15)-MAX($K6,0))*$Q6*10 -> 3.0578035 | V6: =MAX(0,MIN($L6,30)-MAX($K6,15))*$Q6*10 -> 0 | W6: =MAX(0,MIN($L6,50)-MAX($K6,30))*$Q6*10 -> 0 | X6: =MAX(0,MIN($L6,100)-MAX($K6,50))*$Q6*10 -> 0 | Y6: 0.0210883 | Z6: =Q6-Y6 -> 0
A7: 2024 | B7: PM-02-A | C7: PM-02-A-1 | D7: 56.099636 | E7: -87.65064 | F7: 15.2 | G7: 0 | H7: 0 | I7: =H7+F7 -> 15.2 | J7: =IFERROR(INDEX('2. Core Log'!$G$5:$G$12,MATCH(B7,'2. Core Log'!$A$5:$A$12,0)),1) -> 1 | K7: =H7*J7 -> 0 | L7: =I7*J7 -> 15.2 | M7: 0.0827 | N7: 39.1 | O7: 22.7 | P7: =IF(O7="",N7*$C$2,O7) -> 22.7 | Q7: =M7*P7/100*(1-G7) -> 0.0187729 | R7: =Q7*F7 -> 0.28534808 | S7: =R7*10 -> 2.8534808 | T7: =S7*10 -> 28.534808 | U7: =MAX(0,MIN($L7,15)-MAX($K7,0))*$Q7*10 -> 2.815935 | V7: =MAX(0,MIN($L7,30)-MAX($K7,15))*$Q7*10 -> 0.0375458 | W7: =MAX(0,MIN($L7,50)-MAX($K7,30))*$Q7*10 -> 0 | X7: =MAX(0,MIN($L7,100)-MAX($K7,50))*$Q7*10 -> 0 | Y7: 0.0187729 | Z7: =Q7-Y7 -> 0
A8: 2024 | B8: PM-02-A | C8: PM-02-A-2 | D8: 56.099636 | E8: -87.65064 | F8: 5.5 | G8: 0 | H8: =I7 -> 15.2 | I8: =H8+F8 -> 20.7 | J8: =IFERROR(INDEX('2. Core Log'!$G$5:$G$12,MATCH(B8,'2. Core Log'!$A$5:$A$12,0)),1) -> 1 | K8: =H8*J8 -> 15.2 | L8: =I8*J8 -> 20.7 | M8: 0.2662 | N8: 2.71 | O8: 1.57 | P8: =IF(O8="",N8*$C$2,O8) -> 1.57 | Q8: =M8*P8/100*(1-G8) -> 0.00417934 | R8: =Q8*F8 -> 0.02298637 | S8: =R8*10 -> 0.2298637 | T8: =S8*10 -> 2.298637 | U8: =MAX(0,MIN($L8,15)-MAX($K8,0))*$Q8*10 -> 0 | V8: =MAX(0,MIN($L8,30)-MAX($K8,15))*$Q8*10 -> 0.2298637 | W8: =MAX(0,MIN($L8,50)-MAX($K8,30))*$Q8*10 -> 0 | X8: =MAX(0,MIN($L8,100)-MAX($K8,50))*$Q8*10 -> 0 | Y8: 0.00417934 | Z8: =Q8-Y8 -> 0
A9: 2024 | B9: PM-03-A | C9: PM-03-A-1 | D9: 56.110356 | E9: -87.67839 | F9: 8.625 | G9: 0 | H9: 0 | I9: =H9+F9 -> 8.625 | J9: =IFERROR(INDEX('2. Core Log'!$G$5:$G$12,MATCH(B9,'2. Core Log'!$A$5:$A$12,0)),1) -> 1 | K9: =H9*J9 -> 0 | L9: =I9*J9 -> 8.625 | M9: 0.0501 | N9: 62.9 | O9: 36.5 | P9: =IF(O9="",N9*$C$2,O9) -> 36.5 | Q9: =M9*P9/100*(1-G9) -> 0.0182865 | R9: =Q9*F9 -> 0.15772106 | S9: =R9*10 -> 1.5772106 | T9: =S9*10 -> 15.772106 | U9: =MAX(0,MIN($L9,15)-MAX($K9,0))*$Q9*10 -> 1.5772106 | V9: =MAX(0,MIN($L9,30)-MAX($K9,15))*$Q9*10 -> 0 | W9: =MAX(0,MIN($L9,50)-MAX($K9,30))*$Q9*10 -> 0 | X9: =MAX(0,MIN($L9,100)-MAX($K9,50))*$Q9*10 -> 0 | Y9: 0.0182865 | Z9: =Q9-Y9 -> 0
A10: 2024 | B10: PM-03-A | C10: PM-03-A-2 | D10: 56.110356 | E10: -87.67839 | F10: 8.75 | G10: 0 | H10: =I9 -> 8.625 | I10: =H10+F10 -> 17.375 | J10: =IFERROR(INDEX('2. Core Log'!$G$5:$G$12,MATCH(B10,'2. Core Log'!$A$5:$A$12,0)),1) -> 1 | K10: =H10*J10 -> 8.625 | L10: =I10*J10 -> 17.375 | M10: 0.0759 | N10: 73.1 | O10: 42.4 | P10: =IF(O10="",N10*$C$2,O10) -> 42.4 | Q10: =M10*P10/100*(1-G10) -> 0.0321816 | R10: =Q10*F10 -> 0.281589 | S10: =R10*10 -> 2.81589 | T10: =S10*10 -> 28.1589 | U10: =MAX(0,MIN($L10,15)-MAX($K10,0))*$Q10*10 -> 2.051577 | V10: =MAX(0,MIN($L10,30)-MAX($K10,15))*$Q10*10 -> 0.764313 | W10: =MAX(0,MIN($L10,50)-MAX($K10,30))*$Q10*10 -> 0 | X10: =MAX(0,MIN($L10,100)-MAX($K10,50))*$Q10*10 -> 0 | Y10: 0.0321816 | Z10: =Q10-Y10 -> 0
A11: 2024 | B11: PM-03-A | C11: PM-03-A-3 | D11: 56.110356 | E11: -87.67839 | F11: 7.85 | G11: 0 | H11: =I10 -> 17.375 | I11: =H11+F11 -> 25.225 | J11: =IFERROR(INDEX('2. Core Log'!$G$5:$G$12,MATCH(B11,'2. Core Log'!$A$5:$A$12,0)),1) -> 1 | K11: =H11*J11 -> 17.375 | L11: =I11*J11 -> 25.225 | M11: 0.1459 | N11: 67.1 | O11: 38.9 | P11: =IF(O11="",N11*$C$2,O11) -> 38.9 | Q11: =M11*P11/100*(1-G11) -> 0.0567551 | R11: =Q11*F11 -> 0.44552753 | S11: =R11*10 -> 4.4552753 | T11: =S11*10 -> 44.552754 | U11: =MAX(0,MIN($L11,15)-MAX($K11,0))*$Q11*10 -> 0 | V11: =MAX(0,MIN($L11,30)-MAX($K11,15))*$Q11*10 -> 4.4552753 | W11: =MAX(0,MIN($L11,50)-MAX($K11,30))*$Q11*10 -> 0 | X11: =MAX(0,MIN($L11,100)-MAX($K11,50))*$Q11*10 -> 0 | Y11: 0.0567551 | Z11: =Q11-Y11 -> 0
A12: 2024 | B12: PM-03-A | C12: PM-03-A-4 | D12: 56.110356 | E12: -87.67839 | F12: 5.5 | G12: 0 | H12: =I11 -> 25.225 | I12: =H12+F12 -> 30.725 | J12: =IFERROR(INDEX('2. Core Log'!$G$5:$G$12,MATCH(B12,'2. Core Log'!$A$5:$A$12,0)),1) -> 1 | K12: =H12*J12 -> 25.225 | L12: =I12*J12 -> 30.725 | M12: 0.2287 | N12: 18.4 | O12: 10.7 | P12: =IF(O12="",N12*$C$2,O12) -> 10.7 | Q12: =M12*P12/100*(1-G12) -> 0.0244709 | R12: =Q12*F12 -> 0.13458995 | S12: =R12*10 -> 1.3458995 | T12: =S12*10 -> 13.458995 | U12: =MAX(0,MIN($L12,15)-MAX($K12,0))*$Q12*10 -> 0 | V12: =MAX(0,MIN($L12,30)-MAX($K12,15))*$Q12*10 -> 1.1684855 | W12: =MAX(0,MIN($L12,50)-MAX($K12,30))*$Q12*10 -> 0.17741403 | X12: =MAX(0,MIN($L12,100)-MAX($K12,50))*$Q12*10 -> 0 | Y12: 0.0244709 | Z12: =Q12-Y12 -> 0
A13: 2025 | B13: FS-05 | C13: FS-05-1 | D13: 56.079389 | E13: -87.75622 | F13: 10 | G13: 0 | H13: 0 | I13: =H13+F13 -> 10 | J13: =IFERROR(INDEX('2. Core Log'!$G$5:$G$12,MATCH(B13,'2. Core Log'!$A$5:$A$12,0)),1) -> 1 | K13: =H13*J13 -> 0 | L13: =I13*J13 -> 10 | M13: 0.27948308 | N13: 15.6 | O13: 8.6 | P13: =IF(O13="",N13*$C$2,O13) -> 8.6 | Q13: =M13*P13/100*(1-G13) -> 0.024035545 | R13: =Q13*F13 -> 0.24035545 | S13: =R13*10 -> 2.4035545 | T13: =S13*10 -> 24.035545 | U13: =MAX(0,MIN($L13,15)-MAX($K13,0))*$Q13*10 -> 2.4035545 | V13: =MAX(0,MIN($L13,30)-MAX($K13,15))*$Q13*10 -> 0 | W13: =MAX(0,MIN($L13,50)-MAX($K13,30))*$Q13*10 -> 0 | X13: =MAX(0,MIN($L13,100)-MAX($K13,50))*$Q13*10 -> 0 | Y13: 0.024035545 | Z13: =Q13-Y13 -> -4.64e-10
A14: 2025 | B14: FS-05 | C14: FS-05-2 | D14: 56.079389 | E14: -87.75622 | F14: 10 | G14: 0 | H14: =I13 -> 10 | I14: =H14+F14 -> 20 | J14: =IFERROR(INDEX('2. Core Log'!$G$5:$G$12,MATCH(B14,'2. Core Log'!$A$5:$A$12,0)),1) -> 1 | K14: =H14*J14 -> 10 | L14: =I14*J14 -> 20 | M14: 2.0365201 | N14: 2.1 | O14: 1.1 | P14: =IF(O14="",N14*$C$2,O14) -> 1.1 | Q14: =M14*P14/100*(1-G14) -> 0.022401721 | R14: =Q14*F14 -> 0.22401721 | S14: =R14*10 -> 2.2401721 | T14: =S14*10 -> 22.401721 | U14: =MAX(0,MIN($L14,15)-MAX($K14,0))*$Q14*10 -> 1.1200861 | V14: =MAX(0,MIN($L14,30)-MAX($K14,15))*$Q14*10 -> 1.1200861 | W14: =MAX(0,MIN($L14,50)-MAX($K14,30))*$Q14*10 -> 0 | X14: =MAX(0,MIN($L14,100)-MAX($K14,50))*$Q14*10 -> 0 | Y14: 0.022401721 | Z14: =Q14-Y14 -> 1.77e-10
A15: 2025 | B15: FS-05 | C15: FS-05-3 | D15: 56.079389 | E15: -87.75622 | F15: 10 | G15: 0 | H15: =I14 -> 20 | I15: =H15+F15 -> 30 | J15: =IFERROR(INDEX('2. Core Log'!$G$5:$G$12,MATCH(B15,'2. Core Log'!$A$5:$A$12,0)),1) -> 1 | K15: =H15*J15 -> 20 | L15: =I15*J15 -> 30 | M15: 1.6241369 | N15: 1.6 | O15: 0.9 | P15: =IF(O15="",N15*$C$2,O15) -> 0.9 | Q15: =M15*P15/100*(1-G15) -> 0.014617232 | R15: =Q15*F15 -> 0.14617232 | S15: =R15*10 -> 1.4617232 | T15: =S15*10 -> 14.617232 | U15: =MAX(0,MIN($L15,15)-MAX($K15,0))*$Q15*10 -> 0 | V15: =MAX(0,MIN($L15,30)-MAX($K15,15))*$Q15*10 -> 1.4617232 | W15: =MAX(0,MIN($L15,50)-MAX($K15,30))*$Q15*10 -> 0 | X15: =MAX(0,MIN($L15,100)-MAX($K15,50))*$Q15*10 -> 0 | Y15: 0.014617232 | Z15: =Q15-Y15 -> 1.27e-10
A16: 2025 | B16: FS-04 | C16: FS-04-1 | D16: 56.074278 | E16: -87.79556 | F16: 10 | G16: 0 | H16: 0 | I16: =H16+F16 -> 10 | J16: =IFERROR(INDEX('2. Core Log'!$G$5:$G$12,MATCH(B16,'2. Core Log'!$A$5:$A$12,0)),1) -> 1 | K16: =H16*J16 -> 0 | L16: =I16*J16 -> 10 | M16: 1.974657 | N16: 5.5 | O16: 3.1 | P16: =IF(O16="",N16*$C$2,O16) -> 3.1 | Q16: =M16*P16/100*(1-G16) -> 0.061214368 | R16: =Q16*F16 -> 0.61214368 | S16: =R16*10 -> 6.1214368 | T16: =S16*10 -> 61.214368 | U16: =MAX(0,MIN($L16,15)-MAX($K16,0))*$Q16*10 -> 6.1214368 | V16: =MAX(0,MIN($L16,30)-MAX($K16,15))*$Q16*10 -> 0 | W16: =MAX(0,MIN($L16,50)-MAX($K16,30))*$Q16*10 -> 0 | X16: =MAX(0,MIN($L16,100)-MAX($K16,50))*$Q16*10 -> 0 | Y16: 0.061214368 | Z16: =Q16-Y16 -> 5.4000006e-11
A17: 2025 | B17: FS-04 | C17: FS-04-2 | D17: 56.074278 | E17: -87.79556 | F17: 10 | G17: 0 | H17: =I16 -> 10 | I17: =H17+F17 -> 20 | J17: =IFERROR(INDEX('2. Core Log'!$G$5:$G$12,MATCH(B17,'2. Core Log'!$A$5:$A$12,0)),1) -> 1 | K17: =H17*J17 -> 10 | L17: =I17*J17 -> 20 | M17: 0.99685946 | N17: 3.2 | O17: 1.8 | P17: =IF(O17="",N17*$C$2,O17) -> 1.8 | Q17: =M17*P17/100*(1-G17) -> 0.01794347 | R17: =Q17*F17 -> 0.1794347 | S17: =R17*10 -> 1.794347 | T17: =S17*10 -> 17.94347 | U17: =MAX(0,MIN($L17,15)-MAX($K17,0))*$Q17*10 -> 0.89717351 | V17: =MAX(0,MIN($L17,30)-MAX($K17,15))*$Q17*10 -> 0.89717351 | W17: =MAX(0,MIN($L17,50)-MAX($K17,30))*$Q17*10 -> 0 | X17: =MAX(0,MIN($L17,100)-MAX($K17,50))*$Q17*10 -> 0 | Y17: 0.01794347 | Z17: =Q17-Y17 -> 2.62e-10
A18: 2025 | B18: FS-04 | C18: FS-04-3 | D18: 56.074278 | E18: -87.79556 | F18: 10 | G18: 0 | H18: =I17 -> 20 | I18: =H18+F18 -> 30 | J18: =IFERROR(INDEX('2. Core Log'!$G$5:$G$12,MATCH(B18,'2. Core Log'!$A$5:$A$12,0)),1) -> 1 | K18: =H18*J18 -> 20 | L18: =I18*J18 -> 30 | M18: 1.0537351 | N18: 1.5 | O18: 0.8 | P18: =IF(O18="",N18*$C$2,O18) -> 0.8 | Q18: =M18*P18/100*(1-G18) -> 0.0084298811 | R18: =Q18*F18 -> 0.084298811 | S18: =R18*10 -> 0.84298811 | T18: =S18*10 -> 8.4298811 | U18: =MAX(0,MIN($L18,15)-MAX($K18,0))*$Q18*10 -> 0 | V18: =MAX(0,MIN($L18,30)-MAX($K18,15))*$Q18*10 -> 0.84298811 | W18: =MAX(0,MIN($L18,50)-MAX($K18,30))*$Q18*10 -> 0 | X18: =MAX(0,MIN($L18,100)-MAX($K18,50))*$Q18*10 -> 0 | Y18: 0.008429881 | Z18: =Q18-Y18 -> 8e-11
A19: 2025 | B19: FS-03 | C19: FS-03-1 | D19: 56.128917 | E19: -87.87181 | F19: 10 | G19: 0 | H19: 0 | I19: =H19+F19 -> 10 | J19: =IFERROR(INDEX('2. Core Log'!$G$5:$G$12,MATCH(B19,'2. Core Log'!$A$5:$A$12,0)),1) -> 1 | K19: =H19*J19 -> 0 | L19: =I19*J19 -> 10 | M19: 2.0632819 | N19: 1.8 | O19: 1 | P19: =IF(O19="",N19*$C$2,O19) -> 1 | Q19: =M19*P19/100*(1-G19) -> 0.020632819 | R19: =Q19*F19 -> 0.20632819 | S19: =R19*10 -> 2.0632819 | T19: =S19*10 -> 20.632819 | U19: =MAX(0,MIN($L19,15)-MAX($K19,0))*$Q19*10 -> 2.0632819 | V19: =MAX(0,MIN($L19,30)-MAX($K19,15))*$Q19*10 -> 0 | W19: =MAX(0,MIN($L19,50)-MAX($K19,30))*$Q19*10 -> 0 | X19: =MAX(0,MIN($L19,100)-MAX($K19,50))*$Q19*10 -> 0 | Y19: 0.020632819 | Z19: =Q19-Y19 -> 3.2e-10
A20: 2025 | B20: FS-03 | C20: FS-03-2 | D20: 56.128917 | E20: -87.87181 | F20: 10 | G20: 0 | H20: =I19 -> 10 | I20: =H20+F20 -> 20 | J20: =IFERROR(INDEX('2. Core Log'!$G$5:$G$12,MATCH(B20,'2. Core Log'!$A$5:$A$12,0)),1) -> 1 | K20: =H20*J20 -> 10 | L20: =I20*J20 -> 20 | M20: 2.1814325 | N20: 0.9 | O20: 0.5 | P20: =IF(O20="",N20*$C$2,O20) -> 0.5 | Q20: =M20*P20/100*(1-G20) -> 0.010907162 | R20: =Q20*F20 -> 0.10907162 | S20: =R20*10 -> 1.0907162 | T20: =S20*10 -> 10.907162 | U20: =MAX(0,MIN($L20,15)-MAX($K20,0))*$Q20*10 -> 0.54535811 | V20: =MAX(0,MIN($L20,30)-MAX($K20,15))*$Q20*10 -> 0.54535811 | W20: =MAX(0,MIN($L20,50)-MAX($K20,30))*$Q20*10 -> 0 | X20: =MAX(0,MIN($L20,100)-MAX($K20,50))*$Q20*10 -> 0 | Y20: 0.010907162 | Z20: =Q20-Y20 -> 2.55e-10
A21: 2025 | B21: FS-03 | C21: FS-03-3 | D21: 56.128917 | E21: -87.87181 | F21: 10 | G21: 0 | H21: =I20 -> 20 | I21: =H21+F21 -> 30 | J21: =IFERROR(INDEX('2. Core Log'!$G$5:$G$12,MATCH(B21,'2. Core Log'!$A$5:$A$12,0)),1) -> 1 | K21: =H21*J21 -> 20 | L21: =I21*J21 -> 30 | M21: 2.1366099 | N21: 0.8 | O21: 0.5 | P21: =IF(O21="",N21*$C$2,O21) -> 0.5 | Q21: =M21*P21/100*(1-G21) -> 0.01068305 | R21: =Q21*F21 -> 0.1068305 | S21: =R21*10 -> 1.068305 | T21: =S21*10 -> 10.68305 | U21: =MAX(0,MIN($L21,15)-MAX($K21,0))*$Q21*10 -> 0 | V21: =MAX(0,MIN($L21,30)-MAX($K21,15))*$Q21*10 -> 1.068305 | W21: =MAX(0,MIN($L21,50)-MAX($K21,30))*$Q21*10 -> 0 | X21: =MAX(0,MIN($L21,100)-MAX($K21,50))*$Q21*10 -> 0 | Y21: 0.01068305 | Z21: =Q21-Y21 -> -3.9e-10
A22: 2025 | B22: FS-02 | C22: FS-02-1 | D22: 55.992611 | E22: -87.62825 | F22: 10 | G22: 0 | H22: 0 | I22: =H22+F22 -> 10 | J22: =IFERROR(INDEX('2. Core Log'!$G$5:$G$12,MATCH(B22,'2. Core Log'!$A$5:$A$12,0)),1) -> 1 | K22: =H22*J22 -> 0 | L22: =I22*J22 -> 10 | M22: 0.74666579 | N22: 9.4 | O22: 5.2 | P22: =IF(O22="",N22*$C$2,O22) -> 5.2 | Q22: =M22*P22/100*(1-G22) -> 0.038826621 | R22: =Q22*F22 -> 0.38826621 | S22: =R22*10 -> 3.8826621 | T22: =S22*10 -> 38.826621 | U22: =MAX(0,MIN($L22,15)-MAX($K22,0))*$Q22*10 -> 3.8826621 | V22: =MAX(0,MIN($L22,30)-MAX($K22,15))*$Q22*10 -> 0 | W22: =MAX(0,MIN($L22,50)-MAX($K22,30))*$Q22*10 -> 0 | X22: =MAX(0,MIN($L22,100)-MAX($K22,50))*$Q22*10 -> 0 | Y22: 0.038826621 | Z22: =Q22-Y22 -> 1.32e-10
A23: 2025 | B23: FS-02 | C23: FS-02-2 | D23: 55.992611 | E23: -87.62825 | F23: 10 | G23: 0 | H23: =I22 -> 10 | I23: =H23+F23 -> 20 | J23: =IFERROR(INDEX('2. Core Log'!$G$5:$G$12,MATCH(B23,'2. Core Log'!$A$5:$A$12,0)),1) -> 1 | K23: =H23*J23 -> 10 | L23: =I23*J23 -> 20 | M23: 1.497014 | N23: 3.5 | O23: 1.9 | P23: =IF(O23="",N23*$C$2,O23) -> 1.9 | Q23: =M23*P23/100*(1-G23) -> 0.028443267 | R23: =Q23*F23 -> 0.28443267 | S23: =R23*10 -> 2.8443267 | T23: =S23*10 -> 28.443267 | U23: =MAX(0,MIN($L23,15)-MAX($K23,0))*$Q23*10 -> 1.4221633 | V23: =MAX(0,MIN($L23,30)-MAX($K23,15))*$Q23*10 -> 1.4221633 | W23: =MAX(0,MIN($L23,50)-MAX($K23,30))*$Q23*10 -> 0 | X23: =MAX(0,MIN($L23,100)-MAX($K23,50))*$Q23*10 -> 0 | Y23: 0.028443267 | Z23: =Q23-Y23 -> -5.0000001e-11
A24: 2025 | B24: FS-02 | C24: FS-02-3 | D24: 55.992611 | E24: -87.62825 | F24: 10 | G24: 0 | H24: =I23 -> 20 | I24: =H24+F24 -> 30 | J24: =IFERROR(INDEX('2. Core Log'!$G$5:$G$12,MATCH(B24,'2. Core Log'!$A$5:$A$12,0)),1) -> 1 | K24: =H24*J24 -> 20 | L24: =I24*J24 -> 30 | M24: 1.1030484 | N24: 2.7 | O24: 1.5 | P24: =IF(O24="",N24*$C$2,O24) -> 1.5 | Q24: =M24*P24/100*(1-G24) -> 0.016545726 | R24: =Q24*F24 -> 0.16545726 | S24: =R24*10 -> 1.6545726 | T24: =S24*10 -> 16.545726 | U24: =MAX(0,MIN($L24,15)-MAX($K24,0))*$Q24*10 -> 0 | V24: =MAX(0,MIN($L24,30)-MAX($K24,15))*$Q24*10 -> 1.6545726 | W24: =MAX(0,MIN($L24,50)-MAX($K24,30))*$Q24*10 -> 0 | X24: =MAX(0,MIN($L24,100)-MAX($K24,50))*$Q24*10 -> 0 | Y24: 0.016545726 | Z24: =Q24-Y24 -> 3e-10
A25: 2025 | B25: FS-01 | C25: FS-01-1 | D25: 55.965999 | E25: -87.6282 | F25: 10 | G25: 0 | H25: 0 | I25: =H25+F25 -> 10 | J25: =IFERROR(INDEX('2. Core Log'!$G$5:$G$12,MATCH(B25,'2. Core Log'!$A$5:$A$12,0)),1) -> 1 | K25: =H25*J25 -> 0 | L25: =I25*J25 -> 10 | M25: 1.7629047 | N25: 5.4 | O25: 3 | P25: =IF(O25="",N25*$C$2,O25) -> 3 | Q25: =M25*P25/100*(1-G25) -> 0.052887141 | R25: =Q25*F25 -> 0.52887141 | S25: =R25*10 -> 5.2887141 | T25: =S25*10 -> 52.887141 | U25: =MAX(0,MIN($L25,15)-MAX($K25,0))*$Q25*10 -> 5.2887141 | V25: =MAX(0,MIN($L25,30)-MAX($K25,15))*$Q25*10 -> 0 | W25: =MAX(0,MIN($L25,50)-MAX($K25,30))*$Q25*10 -> 0 | X25: =MAX(0,MIN($L25,100)-MAX($K25,50))*$Q25*10 -> 0 | Y25: 0.052887141 | Z25: =Q25-Y25 -> -5.9999998e-11
A26: 2025 | B26: FS-01 | C26: FS-01-2 | D26: 55.965999 | E26: -87.6282 | F26: 10 | G26: 0 | H26: =I25 -> 10 | I26: =H26+F26 -> 20 | J26: =IFERROR(INDEX('2. Core Log'!$G$5:$G$12,MATCH(B26,'2. Core Log'!$A$5:$A$12,0)),1) -> 1 | K26: =H26*J26 -> 10 | L26: =I26*J26 -> 20 | M26: 1.5938661 | N26: 7.3 | O26: 4.1 | P26: =IF(O26="",N26*$C$2,O26) -> 4.1 | Q26: =M26*P26/100*(1-G26) -> 0.065348508 | R26: =Q26*F26 -> 0.65348508 | S26: =R26*10 -> 6.5348508 | T26: =S26*10 -> 65.348508 | U26: =MAX(0,MIN($L26,15)-MAX($K26,0))*$Q26*10 -> 3.2674254 | V26: =MAX(0,MIN($L26,30)-MAX($K26,15))*$Q26*10 -> 3.2674254 | W26: =MAX(0,MIN($L26,50)-MAX($K26,30))*$Q26*10 -> 0 | X26: =MAX(0,MIN($L26,100)-MAX($K26,50))*$Q26*10 -> 0 | Y26: 0.065348508 | Z26: =Q26-Y26 -> 4.6e-10
A27: 2025 | B27: FS-01 | C27: FS-01-3 | D27: 55.965999 | E27: -87.6282 | F27: 10 | G27: 0 | H27: =I26 -> 20 | I27: =H27+F27 -> 30 | J27: =IFERROR(INDEX('2. Core Log'!$G$5:$G$12,MATCH(B27,'2. Core Log'!$A$5:$A$12,0)),1) -> 1 | K27: =H27*J27 -> 20 | L27: =I27*J27 -> 30 | M27: 1.4349645 | N27: 3 | O27: 1.7 | P27: =IF(O27="",N27*$C$2,O27) -> 1.7 | Q27: =M27*P27/100*(1-G27) -> 0.024394396 | R27: =Q27*F27 -> 0.24394396 | S27: =R27*10 -> 2.4394396 | T27: =S27*10 -> 24.394396 | U27: =MAX(0,MIN($L27,15)-MAX($K27,0))*$Q27*10 -> 0 | V27: =MAX(0,MIN($L27,30)-MAX($K27,15))*$Q27*10 -> 2.4394396 | W27: =MAX(0,MIN($L27,50)-MAX($K27,30))*$Q27*10 -> 0 | X27: =MAX(0,MIN($L27,100)-MAX($K27,50))*$Q27*10 -> 0 | Y27: 0.024394396 | Z27: =Q27-Y27 -> 4.32e-10
C28: Total / max |check| | S28: =SUM(S6:S27) -> 58.066514 | T28: =SUM(T6:T27) -> 580.66514 | U28: =SUM(U6:U27) -> 36.514382 | V28: =SUM(V6:V27) -> 21.374718 | W28: =SUM(W6:W27) -> 0.17741403 | X28: =SUM(X6:X27) -> 0 | Z28: =SUMPRODUCT(MAX(ABS(Z6:Z27))) -> 4.64e-10
C29: Column-U–X totals are the whole-dataset stock in each target interval, not a per-core value — see sheet 4 for per-core numbers.

Sheet 4. Core Summary
A1: Sheet 4 — Core Summary (fully automatic — nothing to type here)
A2: A target interval with no core material reports 'no core material', not 0. 0–30 cm is the response variable step 3 extracts covariates against — use only rows flagged 'full 0–30 cm coverage'.
A4: Core Id | B4: Year | C4: Latitude (°N) | D4: Longitude (°E) | E4: Slices | F4: In-situ core depth (cm) | G4: Whole-core stock (kg C/m²) | H4: Whole-core stock (Mg C/ha) | I4: 0–15 cm (kg C/m²) | J4: 15–30 cm (kg C/m²) | K4: 30–50 cm (kg C/m²) | L4: 50–100 cm (kg C/m²) | M4: 0–30 cm (kg C/m²) | N4: 0–30 cm (Mg C/ha) | O4: Depth coverage flag
A5: ='2. Core Log'!A5 -> PM-01-A | B5: ='2. Core Log'!B5 -> 2024 | C5: ='2. Core Log'!C5 -> 56.098575 | D5: ='2. Core Log'!D5 -> -87.67978 | E5: ='2. Core Log'!H5 -> 1 | F5: ='2. Core Log'!J5 -> 14.5 | G5: =SUMIF('3. Sample Data'!$B$6:$B$27,$A5,'3. Sample Data'!$S$6:$S$27) -> 3.0578035 | H5: =G5*10 -> 30.578035 | I5: =IF($F5<=0,"no core material",SUMIF('3. Sample Data'!$B$6:$B$27,$A5,'3. Sample Data'!$U$6:$U$27)) -> 3.0578035 | J5: =IF($F5<=15,"no core material",SUMIF('3. Sample Data'!$B$6:$B$27,$A5,'3. Sample Data'!$V$6:$V$27)) -> no core material | K5: =IF($F5<=30,"no core material",SUMIF('3. Sample Data'!$B$6:$B$27,$A5,'3. Sample Data'!$W$6:$W$27)) -> no core material | L5: =IF($F5<=50,"no core material",SUMIF('3. Sample Data'!$B$6:$B$27,$A5,'3. Sample Data'!$X$6:$X$27)) -> no core material | M5: =SUMIF('3. Sample Data'!$B$6:$B$27,$A5,'3. Sample Data'!$U$6:$U$27)+SUMIF('3. Sample Data'!$B$6:$B$27,$A5,'3. Sample Data'!$V$6:$V$27) -> 3.0578035 | N5: =M5*10 -> 30.578035 | O5: =IF($F5>=30,"full 0–30 cm coverage","PARTIAL — core stops at "&TEXT($F5,"0.0")&" cm; 0–30 cm stock covers only "&TEXT($F5/30,"0%")&" of the interval") -> PARTIAL — core stops at 14.5 cm; 0–30 cm stock covers only 48% of the interval
A6: ='2. Core Log'!A6 -> PM-02-A | B6: ='2. Core Log'!B6 -> 2024 | C6: ='2. Core Log'!C6 -> 56.099636 | D6: ='2. Core Log'!D6 -> -87.65064 | E6: ='2. Core Log'!H6 -> 2 | F6: ='2. Core Log'!J6 -> 20.7 | G6: =SUMIF('3. Sample Data'!$B$6:$B$27,$A6,'3. Sample Data'!$S$6:$S$27) -> 3.0833445 | H6: =G6*10 -> 30.833445 | I6: =IF($F6<=0,"no core material",SUMIF('3. Sample Data'!$B$6:$B$27,$A6,'3. Sample Data'!$U$6:$U$27)) -> 2.815935 | J6: =IF($F6<=15,"no core material",SUMIF('3. Sample Data'!$B$6:$B$27,$A6,'3. Sample Data'!$V$6:$V$27)) -> 0.2674095 | K6: =IF($F6<=30,"no core material",SUMIF('3. Sample Data'!$B$6:$B$27,$A6,'3. Sample Data'!$W$6:$W$27)) -> no core material | L6: =IF($F6<=50,"no core material",SUMIF('3. Sample Data'!$B$6:$B$27,$A6,'3. Sample Data'!$X$6:$X$27)) -> no core material | M6: =SUMIF('3. Sample Data'!$B$6:$B$27,$A6,'3. Sample Data'!$U$6:$U$27)+SUMIF('3. Sample Data'!$B$6:$B$27,$A6,'3. Sample Data'!$V$6:$V$27) -> 3.0833445 | N6: =M6*10 -> 30.833445 | O6: =IF($F6>=30,"full 0–30 cm coverage","PARTIAL — core stops at "&TEXT($F6,"0.0")&" cm; 0–30 cm stock covers only "&TEXT($F6/30,"0%")&" of the interval") -> PARTIAL — core stops at 20.7 cm; 0–30 cm stock covers only 69% of the interval
A7: ='2. Core Log'!A7 -> PM-03-A | B7: ='2. Core Log'!B7 -> 2024 | C7: ='2. Core Log'!C7 -> 56.110356 | D7: ='2. Core Log'!D7 -> -87.67839 | E7: ='2. Core Log'!H7 -> 4 | F7: ='2. Core Log'!J7 -> 30.725 | G7: =SUMIF('3. Sample Data'!$B$6:$B$27,$A7,'3. Sample Data'!$S$6:$S$27) -> 10.194275 | H7: =G7*10 -> 101.94275 | I7: =IF($F7<=0,"no core material",SUMIF('3. Sample Data'!$B$6:$B$27,$A7,'3. Sample Data'!$U$6:$U$27)) -> 3.6287876 | J7: =IF($F7<=15,"no core material",SUMIF('3. Sample Data'!$B$6:$B$27,$A7,'3. Sample Data'!$V$6:$V$27)) -> 6.3880738 | K7: =IF($F7<=30,"no core material",SUMIF('3. Sample Data'!$B$6:$B$27,$A7,'3. Sample Data'!$W$6:$W$27)) -> 0.17741403 | L7: =IF($F7<=50,"no core material",SUMIF('3. Sample Data'!$B$6:$B$27,$A7,'3. Sample Data'!$X$6:$X$27)) -> no core material | M7: =SUMIF('3. Sample Data'!$B$6:$B$27,$A7,'3. Sample Data'!$U$6:$U$27)+SUMIF('3. Sample Data'!$B$6:$B$27,$A7,'3. Sample Data'!$V$6:$V$27) -> 10.016861 | N7: =M7*10 -> 100.16861 | O7: =IF($F7>=30,"full 0–30 cm coverage","PARTIAL — core stops at "&TEXT($F7,"0.0")&" cm; 0–30 cm stock covers only "&TEXT($F7/30,"0%")&" of the interval") -> full 0–30 cm coverage
A8: ='2. Core Log'!A8 -> FS-05 | B8: ='2. Core Log'!B8 -> 2025 | C8: ='2. Core Log'!C8 -> 56.079389 | D8: ='2. Core Log'!D8 -> -87.75622 | E8: ='2. Core Log'!H8 -> 3 | F8: ='2. Core Log'!J8 -> 30 | G8: =SUMIF('3. Sample Data'!$B$6:$B$27,$A8,'3. Sample Data'!$S$6:$S$27) -> 6.1054498 | H8: =G8*10 -> 61.054498 | I8: =IF($F8<=0,"no core material",SUMIF('3. Sample Data'!$B$6:$B$27,$A8,'3. Sample Data'!$U$6:$U$27)) -> 3.5236405 | J8: =IF($F8<=15,"no core material",SUMIF('3. Sample Data'!$B$6:$B$27,$A8,'3. Sample Data'!$V$6:$V$27)) -> 2.5818093 | K8: =IF($F8<=30,"no core material",SUMIF('3. Sample Data'!$B$6:$B$27,$A8,'3. Sample Data'!$W$6:$W$27)) -> no core material | L8: =IF($F8<=50,"no core material",SUMIF('3. Sample Data'!$B$6:$B$27,$A8,'3. Sample Data'!$X$6:$X$27)) -> no core material | M8: =SUMIF('3. Sample Data'!$B$6:$B$27,$A8,'3. Sample Data'!$U$6:$U$27)+SUMIF('3. Sample Data'!$B$6:$B$27,$A8,'3. Sample Data'!$V$6:$V$27) -> 6.1054498 | N8: =M8*10 -> 61.054498 | O8: =IF($F8>=30,"full 0–30 cm coverage","PARTIAL — core stops at "&TEXT($F8,"0.0")&" cm; 0–30 cm stock covers only "&TEXT($F8/30,"0%")&" of the interval") -> full 0–30 cm coverage
A9: ='2. Core Log'!A9 -> FS-04 | B9: ='2. Core Log'!B9 -> 2025 | C9: ='2. Core Log'!C9 -> 56.074278 | D9: ='2. Core Log'!D9 -> -87.79556 | E9: ='2. Core Log'!H9 -> 3 | F9: ='2. Core Log'!J9 -> 30 | G9: =SUMIF('3. Sample Data'!$B$6:$B$27,$A9,'3. Sample Data'!$S$6:$S$27) -> 8.7587719 | H9: =G9*10 -> 87.587719 | I9: =IF($F9<=0,"no core material",SUMIF('3. Sample Data'!$B$6:$B$27,$A9,'3. Sample Data'!$U$6:$U$27)) -> 7.0186103 | J9: =IF($F9<=15,"no core material",SUMIF('3. Sample Data'!$B$6:$B$27,$A9,'3. Sample Data'!$V$6:$V$27)) -> 1.7401616 | K9: =IF($F9<=30,"no core material",SUMIF('3. Sample Data'!$B$6:$B$27,$A9,'3. Sample Data'!$W$6:$W$27)) -> no core material | L9: =IF($F9<=50,"no core material",SUMIF('3. Sample Data'!$B$6:$B$27,$A9,'3. Sample Data'!$X$6:$X$27)) -> no core material | M9: =SUMIF('3. Sample Data'!$B$6:$B$27,$A9,'3. Sample Data'!$U$6:$U$27)+SUMIF('3. Sample Data'!$B$6:$B$27,$A9,'3. Sample Data'!$V$6:$V$27) -> 8.7587719 | N9: =M9*10 -> 87.587719 | O9: =IF($F9>=30,"full 0–30 cm coverage","PARTIAL — core stops at "&TEXT($F9,"0.0")&" cm; 0–30 cm stock covers only "&TEXT($F9/30,"0%")&" of the interval") -> full 0–30 cm coverage
A10: ='2. Core Log'!A10 -> FS-03 | B10: ='2. Core Log'!B10 -> 2025 | C10: ='2. Core Log'!C10 -> 56.128917 | D10: ='2. Core Log'!D10 -> -87.87181 | E10: ='2. Core Log'!H10 -> 3 | F10: ='2. Core Log'!J10 -> 30 | G10: =SUMIF('3. Sample Data'!$B$6:$B$27,$A10,'3. Sample Data'!$S$6:$S$27) -> 4.2223031 | H10: =G10*10 -> 42.223031 | I10: =IF($F10<=0,"no core material",SUMIF('3. Sample Data'!$B$6:$B$27,$A10,'3. Sample Data'!$U$6:$U$27)) -> 2.60864 | J10: =IF($F10<=15,"no core material",SUMIF('3. Sample Data'!$B$6:$B$27,$A10,'3. Sample Data'!$V$6:$V$27)) -> 1.6136631 | K10: =IF($F10<=30,"no core material",SUMIF('3. Sample Data'!$B$6:$B$27,$A10,'3. Sample Data'!$W$6:$W$27)) -> no core material | L10: =IF($F10<=50,"no core material",SUMIF('3. Sample Data'!$B$6:$B$27,$A10,'3. Sample Data'!$X$6:$X$27)) -> no core material | M10: =SUMIF('3. Sample Data'!$B$6:$B$27,$A10,'3. Sample Data'!$U$6:$U$27)+SUMIF('3. Sample Data'!$B$6:$B$27,$A10,'3. Sample Data'!$V$6:$V$27) -> 4.2223031 | N10: =M10*10 -> 42.223031 | O10: =IF($F10>=30,"full 0–30 cm coverage","PARTIAL — core stops at "&TEXT($F10,"0.0")&" cm; 0–30 cm stock covers only "&TEXT($F10/30,"0%")&" of the interval") -> full 0–30 cm coverage
A11: ='2. Core Log'!A11 -> FS-02 | B11: ='2. Core Log'!B11 -> 2025 | C11: ='2. Core Log'!C11 -> 55.992611 | D11: ='2. Core Log'!D11 -> -87.62825 | E11: ='2. Core Log'!H11 -> 3 | F11: ='2. Core Log'!J11 -> 30 | G11: =SUMIF('3. Sample Data'!$B$6:$B$27,$A11,'3. Sample Data'!$S$6:$S$27) -> 8.3815614 | H11: =G11*10 -> 83.815614 | I11: =IF($F11<=0,"no core material",SUMIF('3. Sample Data'!$B$6:$B$27,$A11,'3. Sample Data'!$U$6:$U$27)) -> 5.3048255 | J11: =IF($F11<=15,"no core material",SUMIF('3. Sample Data'!$B$6:$B$27,$A11,'3. Sample Data'!$V$6:$V$27)) -> 3.076736 | K11: =IF($F11<=30,"no core material",SUMIF('3. Sample Data'!$B$6:$B$27,$A11,'3. Sample Data'!$W$6:$W$27)) -> no core material | L11: =IF($F11<=50,"no core material",SUMIF('3. Sample Data'!$B$6:$B$27,$A11,'3. Sample Data'!$X$6:$X$27)) -> no core material | M11: =SUMIF('3. Sample Data'!$B$6:$B$27,$A11,'3. Sample Data'!$U$6:$U$27)+SUMIF('3. Sample Data'!$B$6:$B$27,$A11,'3. Sample Data'!$V$6:$V$27) -> 8.3815614 | N11: =M11*10 -> 83.815614 | O11: =IF($F11>=30,"full 0–30 cm coverage","PARTIAL — core stops at "&TEXT($F11,"0.0")&" cm; 0–30 cm stock covers only "&TEXT($F11/30,"0%")&" of the interval") -> full 0–30 cm coverage
A12: ='2. Core Log'!A12 -> FS-01 | B12: ='2. Core Log'!B12 -> 2025 | C12: ='2. Core Log'!C12 -> 55.965999 | D12: ='2. Core Log'!D12 -> -87.6282 | E12: ='2. Core Log'!H12 -> 3 | F12: ='2. Core Log'!J12 -> 30 | G12: =SUMIF('3. Sample Data'!$B$6:$B$27,$A12,'3. Sample Data'!$S$6:$S$27) -> 14.263005 | H12: =G12*10 -> 142.63005 | I12: =IF($F12<=0,"no core material",SUMIF('3. Sample Data'!$B$6:$B$27,$A12,'3. Sample Data'!$U$6:$U$27)) -> 8.5561395 | J12: =IF($F12<=15,"no core material",SUMIF('3. Sample Data'!$B$6:$B$27,$A12,'3. Sample Data'!$V$6:$V$27)) -> 5.7068651 | K12: =IF($F12<=30,"no core material",SUMIF('3. Sample Data'!$B$6:$B$27,$A12,'3. Sample Data'!$W$6:$W$27)) -> no core material | L12: =IF($F12<=50,"no core material",SUMIF('3. Sample Data'!$B$6:$B$27,$A12,'3. Sample Data'!$X$6:$X$27)) -> no core material | M12: =SUMIF('3. Sample Data'!$B$6:$B$27,$A12,'3. Sample Data'!$U$6:$U$27)+SUMIF('3. Sample Data'!$B$6:$B$27,$A12,'3. Sample Data'!$V$6:$V$27) -> 14.263005 | N12: =M12*10 -> 142.63005 | O12: =IF($F12>=30,"full 0–30 cm coverage","PARTIAL — core stops at "&TEXT($F12,"0.0")&" cm; 0–30 cm stock covers only "&TEXT($F12/30,"0%")&" of the interval") -> full 0–30 cm coverage
A13: All cores | G13: =SUM(G5:G12) -> 58.066514 | M13: =AVERAGE(M5:M12) -> 7.2361375 | N13: =M13*10 -> 72.361375 | O13: mean 0–30 cm stock over all cores, partial cores included

Sheet 5. R export (layers)
A1: plot_id | B1: depth_from | C1: depth_to | D1: soc | E1: bulk_density | F1: coarse_frag
A2: ='3. Sample Data'!B6 -> PM-01-A | B2: ='3. Sample Data'!K6 -> 0 | C2: ='3. Sample Data'!L6 -> 14.5 | D2: ='3. Sample Data'!P6*10 -> 227 | E2: ='3. Sample Data'!M6 -> 0.0929 | F2: ='3. Sample Data'!G6 -> 0
A3: ='3. Sample Data'!B7 -> PM-02-A | B3: ='3. Sample Data'!K7 -> 0 | C3: ='3. Sample Data'!L7 -> 15.2 | D3: ='3. Sample Data'!P7*10 -> 227 | E3: ='3. Sample Data'!M7 -> 0.0827 | F3: ='3. Sample Data'!G7 -> 0
A4: ='3. Sample Data'!B8 -> PM-02-A | B4: ='3. Sample Data'!K8 -> 15.2 | C4: ='3. Sample Data'!L8 -> 20.7 | D4: ='3. Sample Data'!P8*10 -> 15.7 | E4: ='3. Sample Data'!M8 -> 0.2662 | F4: ='3. Sample Data'!G8 -> 0
A5: ='3. Sample Data'!B9 -> PM-03-A | B5: ='3. Sample Data'!K9 -> 0 | C5: ='3. Sample Data'!L9 -> 8.625 | D5: ='3. Sample Data'!P9*10 -> 365 | E5: ='3. Sample Data'!M9 -> 0.0501 | F5: ='3. Sample Data'!G9 -> 0
A6: ='3. Sample Data'!B10 -> PM-03-A | B6: ='3. Sample Data'!K10 -> 8.625 | C6: ='3. Sample Data'!L10 -> 17.375 | D6: ='3. Sample Data'!P10*10 -> 424 | E6: ='3. Sample Data'!M10 -> 0.0759 | F6: ='3. Sample Data'!G10 -> 0
A7: ='3. Sample Data'!B11 -> PM-03-A | B7: ='3. Sample Data'!K11 -> 17.375 | C7: ='3. Sample Data'!L11 -> 25.225 | D7: ='3. Sample Data'!P11*10 -> 389 | E7: ='3. Sample Data'!M11 -> 0.1459 | F7: ='3. Sample Data'!G11 -> 0
A8: ='3. Sample Data'!B12 -> PM-03-A | B8: ='3. Sample Data'!K12 -> 25.225 | C8: ='3. Sample Data'!L12 -> 30.725 | D8: ='3. Sample Data'!P12*10 -> 107 | E8: ='3. Sample Data'!M12 -> 0.2287 | F8: ='3. Sample Data'!G12 -> 0
A9: ='3. Sample Data'!B13 -> FS-05 | B9: ='3. Sample Data'!K13 -> 0 | C9: ='3. Sample Data'!L13 -> 10 | D9: ='3. Sample Data'!P13*10 -> 86 | E9: ='3. Sample Data'!M13 -> 0.27948308 | F9: ='3. Sample Data'!G13 -> 0
A10: ='3. Sample Data'!B14 -> FS-05 | B10: ='3. Sample Data'!K14 -> 10 | C10: ='3. Sample Data'!L14 -> 20 | D10: ='3. Sample Data'!P14*10 -> 11 | E10: ='3. Sample Data'!M14 -> 2.0365201 | F10: ='3. Sample Data'!G14 -> 0
A11: ='3. Sample Data'!B15 -> FS-05 | B11: ='3. Sample Data'!K15 -> 20 | C11: ='3. Sample Data'!L15 -> 30 | D11: ='3. Sample Data'!P15*10 -> 9 | E11: ='3. Sample Data'!M15 -> 1.6241369 | F11: ='3. Sample Data'!G15 -> 0
A12: ='3. Sample Data'!B16 -> FS-04 | B12: ='3. Sample Data'!K16 -> 0 | C12: ='3. Sample Data'!L16 -> 10 | D12: ='3. Sample Data'!P16*10 -> 31 | E12: ='3. Sample Data'!M16 -> 1.974657 | F12: ='3. Sample Data'!G16 -> 0
A13: ='3. Sample Data'!B17 -> FS-04 | B13: ='3. Sample Data'!K17 -> 10 | C13: ='3. Sample Data'!L17 -> 20 | D13: ='3. Sample Data'!P17*10 -> 18 | E13: ='3. Sample Data'!M17 -> 0.99685946 | F13: ='3. Sample Data'!G17 -> 0
... A23: ='3. Sample Data'!B27 -> FS-01 | B23: ='3. Sample Data'!K27 -> 20 | C23: ='3. Sample Data'!L27 -> 30 | D23: ='3. Sample Data'!P27*10 -> 17 | E23: ='3. Sample Data'!M27 -> 1.4349645 | F23: ='3. Sample Data'!G27 -> 0

Sheet 6. R export (plots)
A1: plot_id | B1: longitude | C1: latitude | D1: observed | E1: observed_units | F1: depth_basis | G1: coverage_flag
A2: ='4. Core Summary'!A5 -> PM-01-A | B2: ='4. Core Summary'!D5 -> -87.67978 | C2: ='4. Core Summary'!C5 -> 56.098575 | D2: ='4. Core Summary'!M5 -> 3.0578035 | E2: kg C/m2 | F2: 0-30 cm | G2: ='4. Core Summary'!O5 -> PARTIAL — core stops at 14.5 cm; 0–30 cm stock covers only 48% of the interval
A3: ='4. Core Summary'!A6 -> PM-02-A | B3: ='4. Core Summary'!D6 -> -87.65064 | C3: ='4. Core Summary'!C6 -> 56.099636 | D3: ='4. Core Summary'!M6 -> 3.0833445 | E3: kg C/m2 | F3: 0-30 cm | G3: ='4. Core Summary'!O6 -> PARTIAL — core stops at 20.7 cm; 0–30 cm stock covers only 69% of the interval
A4: ='4. Core Summary'!A7 -> PM-03-A | B4: ='4. Core Summary'!D7 -> -87.67839 | C4: ='4. Core Summary'!C7 -> 56.110356 | D4: ='4. Core Summary'!M7 -> 10.016861 | E4: kg C/m2 | F4: 0-30 cm | G4: ='4. Core Summary'!O7 -> full 0–30 cm coverage
A5: ='4. Core Summary'!A8 -> FS-05 | B5: ='4. Core Summary'!D8 -> -87.75622 | C5: ='4. Core Summary'!C8 -> 56.079389 | D5: ='4. Core Summary'!M8 -> 6.1054498 | E5: kg C/m2 | F5: 0-30 cm | G5: ='4. Core Summary'!O8 -> full 0–30 cm coverage
A6: ='4. Core Summary'!A9 -> FS-04 | B6: ='4. Core Summary'!D9 -> -87.79556 | C6: ='4. Core Summary'!C9 -> 56.074278 | D6: ='4. Core Summary'!M9 -> 8.7587719 | E6: kg C/m2 | F6: 0-30 cm | G6: ='4. Core Summary'!O9 -> full 0–30 cm coverage
A7: ='4. Core Summary'!A10 -> FS-03 | B7: ='4. Core Summary'!D10 -> -87.87181 | C7: ='4. Core Summary'!C10 -> 56.128917 | D7: ='4. Core Summary'!M10 -> 4.2223031 | E7: kg C/m2 | F7: 0-30 cm | G7: ='4. Core Summary'!O10 -> full 0–30 cm coverage
A8: ='4. Core Summary'!A11 -> FS-02 | B8: ='4. Core Summary'!D11 -> -87.62825 | C8: ='4. Core Summary'!C11 -> 55.992611 | D8: ='4. Core Summary'!M11 -> 8.3815614 | E8: kg C/m2 | F8: 0-30 cm | G8: ='4. Core Summary'!O11 -> full 0–30 cm coverage
A9: ='4. Core Summary'!A12 -> FS-01 | B9: ='4. Core Summary'!D12 -> -87.6282 | C9: ='4. Core Summary'!C12 -> 55.965999 | D9: ='4. Core Summary'!M12 -> 14.263005 | E9: kg C/m2 | F9: 0-30 cm | G9: ='4. Core Summary'!O12 -> full 0–30 cm coverage
